#VRML_SIM R2023b utf8

EXTERNPROTO "https://raw.githubusercontent.com/cyberbotics/webots/R2023b/projects/objects/floors/protos/Floor.proto"
EXTERNPROTO "https://raw.githubusercontent.com/cyberbotics/webots/R2023b/projects/objects/apartment_structure/protos/Wall.proto"
EXTERNPROTO "https://raw.githubusercontent.com/cyberbotics/webots/R2023b/projects/appearances/protos/FormedConcrete.proto"
EXTERNPROTO "https://raw.githubusercontent.com/cyberbotics/webots/R2023b/projects/objects/backgrounds/protos/TexturedBackground.proto"
EXTERNPROTO "https://raw.githubusercontent.com/cyberbotics/webots/R2023b/projects/appearances/protos/Grass.proto"
EXTERNPROTO "https://raw.githubusercontent.com/cyberbotics/webots/R2023b/projects/objects/tables/protos/Table.proto"
EXTERNPROTO "https://raw.githubusercontent.com/cyberbotics/webots/R2023b/projects/appearances/protos/VarnishedPine.proto"

WorldInfo {
}
Viewpoint {
  orientation 0.2724675610486789 0.1625428094251345 -0.9483360497631462 2.1118909707659737
  position 0.8528063478584067 1.7776877244098959 2.3777410870266436
}
TexturedBackground {
  texture "factory"
  skybox FALSE
}
Floor {
  contactMaterial ""
  size 8 8
  appearance Grass {
  }
}
Wall {
  translation 4 0 0
  name "Wall_1"
  size 0.1 8 1.5
  appearance FormedConcrete {
  }
}
Table {
  size 1.2 2.5 0.74
  trayAppearance VarnishedPine {
    colorOverride 0.709804 0.513726 0.352941
    textureTransform TextureTransform {
      scale 10 10
    }
  }
  legAppearance VarnishedPine {
    colorOverride 0 0 0
    textureTransform TextureTransform {
      scale 4 5
    }
  }
}
DEF REDBLOCK Solid {
  translation -0.0892778 -0.16604 0.779969
  rotation 1.4808841998297273e-11 -1.2191364543096444e-09 -1 0.0001986207951523232
  children [
    DEF BRICK_SHAPE Shape {
      appearance PBRAppearance {
        baseColor 0.878431 0.105882 0.141176
        metalness 0
      }
      geometry Box {
        size 0.05 0.02 0.08
      }
    }
  ]
  boundingObject USE BRICK_SHAPE
  physics Physics {
  }
}
Wall {
  translation -4 0 0
  name "Wall_2"
  size 0.1 8 1.5
  appearance FormedConcrete {
  }
}
Wall {
  translation -0.01 -4 0
  rotation 0 0 1 -1.5707953071795862
  name "Wall_3"
  size 0.1 8.1 1.5
  appearance FormedConcrete {
  }
}
Wall {
  translation 0 4 0
  rotation 0 0 1 -1.5707953071795862
  name "Wall_4"
  size 0.1 8.1 1.5
  appearance FormedConcrete {
  }
}
DEF PANDA Robot {
  translation -0.406454 0.000803724 0.74
  children [
    DEF link0_visual CadShape {
      url [
        "/home/matteo/Repository/Tesi/src/arm_environment/meshes/visual/link0.dae"
      ]
    }
    HingeJoint {
      jointParameters HingeJointParameters {
        axis 0 0 1
        anchor 0 0 0.333
      }
      device [
        RotationalMotor {
          name "panda_joint1"
          maxVelocity 2.175
          minPosition -2.8973
          maxPosition 2.8973
          maxTorque 87
        }
        PositionSensor {
          name "panda_joint1_sensor"
        }
      ]
      endPoint Solid {
        translation 0 0 0.333
        children [
          DEF link1_visual CadShape {
            url [
              "/home/matteo/Repository/Tesi/src/arm_environment/meshes/visual/link1.dae"
            ]
          }
          HingeJoint {
            jointParameters HingeJointParameters {
              axis 0 1 0
            }
            device [
              RotationalMotor {
                name "panda_joint2"
                maxVelocity 2.175
                minPosition -1.7628
                maxPosition 1.7628
                maxTorque 87
              }
              PositionSensor {
                name "panda_joint2_sensor"
              }
            ]
            endPoint Solid {
              rotation -1 0 0 1.570796
              children [
                DEF link2_visual CadShape {
                  url [
                    "/home/matteo/Repository/Tesi/src/arm_environment/meshes/visual/link2.dae"
                  ]
                }
                HingeJoint {
                  jointParameters HingeJointParameters {
                    axis 0 -1 0
                    anchor 0 -0.316 0
                  }
                  device [
                    RotationalMotor {
                      name "panda_joint3"
                      maxVelocity 2.175
                      minPosition -2.8973
                      maxPosition 2.8973
                      maxTorque 87
                    }
                    PositionSensor {
                      name "panda_joint3_sensor"
                    }
                  ]
                  endPoint Solid {
                    translation 0 -0.316 0
                    rotation 1 0 0 1.570796
                    children [
                      DEF link3_visual CadShape {
                        url [
                          "/home/matteo/Repository/Tesi/src/arm_environment/meshes/visual/link3.dae"
                        ]
                      }
                      HingeJoint {
                        jointParameters HingeJointParameters {
                          position -1.5708
                          axis 0 -1 0
                          anchor 0.0825 0 0
                        }
                        device [
                          RotationalMotor {
                            name "panda_joint4"
                            maxVelocity 2.175
                            minPosition -3.0718
                            maxPosition -0.0698
                            maxTorque 87
                          }
                          PositionSensor {
                            name "panda_joint4_sensor"
                          }
                        ]
                        endPoint Solid {
                          translation 0.0825 0 0
                          rotation 0.5773489358556707 0.5773509358554485 -0.5773509358554485 2.094397
                          children [
                            DEF link4_visual CadShape {
                              url [
                                "/home/matteo/Repository/Tesi/src/arm_environment/meshes/visual/link4.dae"
                              ]
                            }
                            HingeJoint {
                              jointParameters HingeJointParameters {
                                axis 0 1 0
                                anchor -0.0825 0.384 0
                              }
                              device [
                                RotationalMotor {
                                  name "panda_joint5"
                                  maxVelocity 2.61
                                  minPosition -2.8973
                                  maxPosition 2.8973
                                  maxTorque 12
                                }
                                PositionSensor {
                                  name "panda_joint5_sensor"
                                }
                              ]
                              endPoint Solid {
                                translation -0.0825 0.384 0
                                rotation -1 0 0 1.570796
                                children [
                                  DEF link5_visual CadShape {
                                    url [
                                      "/home/matteo/Repository/Tesi/src/arm_environment/meshes/visual/link5.dae"
                                    ]
                                  }
                                  HingeJoint {
                                    jointParameters HingeJointParameters {
                                      axis 0 -1 0
                                    }
                                    device [
                                      RotationalMotor {
                                        name "panda_joint6"
                                        maxVelocity 2.61
                                        minPosition -0.0175
                                        maxPosition 3.7525
                                        maxTorque 12
                                      }
                                      PositionSensor {
                                        name "panda_joint6_sensor"
                                      }
                                    ]
                                    endPoint Solid {
                                      rotation 1 0 0 1.570796
                                      children [
                                        DEF link6_visual CadShape {
                                          url [
                                            "/home/matteo/Repository/Tesi/src/arm_environment/meshes/visual/link6.dae"
                                          ]
                                        }
                                        HingeJoint {
                                          jointParameters HingeJointParameters {
                                            axis 0 -1 0
                                            anchor 0.088 0 0
                                          }
                                          device [
                                            RotationalMotor {
                                              name "panda_joint7"
                                              maxVelocity 2.61
                                              minPosition -2.8973
                                              maxPosition 2.8973
                                              maxTorque 12
                                            }
                                            PositionSensor {
                                              name "panda_joint7_sensor"
                                            }
                                          ]
                                          endPoint Solid {
                                            translation 0.088 0 0
                                            rotation 1 0 0 1.570796
                                            children [
                                              DEF link7_visual CadShape {
                                                url [
                                                  "/home/matteo/Repository/Tesi/src/arm_environment/meshes/visual/link7.dae"
                                                ]
                                              }
                                              Solid {
                                                translation 0 0 0.107
                                                children [
                                                  Solid {
                                                    rotation 0 0 -1 0.785398
                                                    children [
                                                      Pose {
                                                        rotation 0 0 1 -0.785398
                                                        children [
                                                          DEF hand_visual CadShape {
                                                            url [
                                                              "/home/matteo/Repository/Tesi/src/arm_environment/meshes/visual/hand.dae"
                                                            ]
                                                          }
                                                          DEF CAMERA_NODE Group {
                                                            children [
                                                              Camera {
                                                                translation 0.04 0 0.0499999
                                                                rotation 0 1 0 -1.5707953071795862
                                                                children [
                                                                  DEF CAMERA_NODE Shape {
                                                                    appearance PBRAppearance {
                                                                      baseColor 1 0.470588 0
                                                                      metalness 0
                                                                    }
                                                                    geometry Sphere {
                                                                      radius 0.005
                                                                      subdivision 3
                                                                    }
                                                                  }
                                                                ]
                                                                name "panda_camera"
                                                                boundingObject USE CAMERA_NODE
                                                                physics Physics {
                                                                }
                                                                fieldOfView 1.5708
                                                                width 1280
                                                                height 800
                                                              }
                                                              Solid {
                                                                translation 0.03 0 0.04
                                                                children [
                                                                  DEF CAMERA_BLOCK Shape {
                                                                    appearance PBRAppearance {
                                                                      baseColor 0.752941 0.74902 0.737255
                                                                      metalness 0
                                                                    }
                                                                    geometry Box {
                                                                      size 0.03 0.02 0.02
                                                                    }
                                                                  }
                                                                ]
                                                                boundingObject USE CAMERA_BLOCK
                                                                physics Physics {
                                                                }
                                                              }
                                                            ]
                                                          }
                                                          DEF panda_finger_joint1 SliderJoint {
                                                            jointParameters JointParameters {
                                                              position 0.00023939238207918006
                                                              axis 0 1 0
                                                              dampingConstant 0.03
                                                            }
                                                            device [
                                                              LinearMotor {
                                                                name "panda_finger::right"
                                                                maxVelocity 0.2
                                                                minPosition -8.260719345761804e-12
                                                                maxPosition 0.04
                                                                maxForce 100
                                                              }
                                                              PositionSensor {
                                                                name "panda_finger::right_sensor"
                                                              }
                                                            ]
                                                            endPoint DEF panda_leftfinger Solid {
                                                              translation 0 0.00023939238207918006 0.0584
                                                              children [
                                                                CadShape {
                                                                  url [
                                                                    "https://raw.githubusercontent.com/cyberbotics/webots/R2023b/projects/robots/franka_emika/panda/protos/meshes/finger.dae"
                                                                  ]
                                                                }
                                                              ]
                                                              name "panda_leftfinger"
                                                              boundingObject Group {
                                                                children [
                                                                  Pose {
                                                                    translation 0 0.007 0.045
                                                                    children [
                                                                      Box {
                                                                        size 0.018 0.014 0.017
                                                                      }
                                                                    ]
                                                                  }
                                                                  Pose {
                                                                    translation 0 0.0185 0.012
                                                                    children [
                                                                      Box {
                                                                        size 0.02 0.014 0.014
                                                                      }
                                                                    ]
                                                                  }
                                                                  Pose {
                                                                    translation 0 0.0175 0.026
                                                                    rotation 1 0 0 0.523599
                                                                    children [
                                                                      Box {
                                                                        size 0.018 0.007 0.019
                                                                      }
                                                                    ]
                                                                  }
                                                                ]
                                                              }
                                                              physics Physics {
                                                                density -1
                                                                mass 0.015
                                                                centerOfMass [
                                                                  0 0 0
                                                                ]
                                                                inertiaMatrix [
                                                                  2.375e-06 2.375e-06 7.5e-07
                                                                  0 0 0
                                                                ]
                                                              }
                                                            }
                                                          }
                                                          DEF panda_finger_joint2 SliderJoint {
                                                            jointParameters JointParameters {
                                                              position -1.4300445964877892e-09
                                                              axis 0 -1 0
                                                              dampingConstant 0.03
                                                            }
                                                            device [
                                                              LinearMotor {
                                                                name "panda_finger::left"
                                                                maxVelocity 0.2
                                                                minPosition -8.260719345761804e-12
                                                                maxPosition 0.04
                                                                maxForce 100
                                                              }
                                                              PositionSensor {
                                                                name "panda_finger::left_sensor"
                                                              }
                                                            ]
                                                            endPoint DEF panda_rightfinger Solid {
                                                              translation 0 1.4300445964877892e-09 0.0584
                                                              children [
                                                                Pose {
                                                                  rotation 0 0 1 3.141593
                                                                  children [
                                                                    DEF finger CadShape {
                                                                      url [
                                                                        "https://raw.githubusercontent.com/cyberbotics/webots/R2023b/projects/robots/franka_emika/panda/protos/meshes/finger.dae"
                                                                      ]
                                                                    }
                                                                  ]
                                                                }
                                                                Pose {
                                                                  rotation 0 0 1 3.141593
                                                                  children [
                                                                    USE finger
                                                                  ]
                                                                }
                                                              ]
                                                              name "panda_rightfinger"
                                                              boundingObject Group {
                                                                children [
                                                                  Pose {
                                                                    translation 0 -0.007 0.045
                                                                    children [
                                                                      Box {
                                                                        size 0.018 0.014 0.017
                                                                      }
                                                                    ]
                                                                  }
                                                                  Pose {
                                                                    translation 0 -0.0185 0.012
                                                                    children [
                                                                      Box {
                                                                        size 0.02 0.014 0.014
                                                                      }
                                                                    ]
                                                                  }
                                                                  Pose {
                                                                    translation 0 -0.0175 0.026
                                                                    rotation 1 0 0 -0.523599
                                                                    children [
                                                                      Box {
                                                                        size 0.018 0.007 0.019
                                                                      }
                                                                    ]
                                                                  }
                                                                ]
                                                              }
                                                              physics Physics {
                                                                density -1
                                                                mass 0.015
                                                                centerOfMass [
                                                                  0 0 0
                                                                ]
                                                                inertiaMatrix [
                                                                  2.375e-06 2.375e-06 7.5e-07
                                                                  0 0 0
                                                                ]
                                                              }
                                                            }
                                                          }
                                                        ]
                                                      }
                                                    ]
                                                    name "panda_hand"
                                                    boundingObject Group {
                                                      children [
                                                        Cylinder {
                                                          height 0.1
                                                          radius 0.04
                                                        }
                                                        Sphere {
                                                          radius 0.04
                                                        }
                                                        Sphere {
                                                          radius 0.04
                                                        }
                                                        Cylinder {
                                                          height 0.1
                                                          radius 0.02
                                                        }
                                                        Sphere {
                                                          radius 0.02
                                                        }
                                                        Sphere {
                                                          radius 0.02
                                                        }
                                                      ]
                                                    }
                                                    physics Physics {
                                                    }
                                                  }
                                                  Group {
                                                  }
                                                ]
                                                name "panda_link8"
                                                boundingObject Group {
                                                  children [
                                                    Cylinder {
                                                      height 0.01
                                                      radius 0.03
                                                    }
                                                    Sphere {
                                                      radius 0.03
                                                    }
                                                    Sphere {
                                                      radius 0.03
                                                    }
                                                  ]
                                                }
                                                physics Physics {
                                                }
                                              }
                                            ]
                                            name "panda_link7"
                                            boundingObject Group {
                                              children [
                                                Cylinder {
                                                  height 0.14
                                                  radius 0.04
                                                }
                                                Sphere {
                                                  radius 0.025
                                                }
                                                Sphere {
                                                  radius 0.04
                                                }
                                              ]
                                            }
                                            physics Physics {
                                            }
                                          }
                                        }
                                      ]
                                      name "panda_link6"
                                      boundingObject Group {
                                        children [
                                          Cylinder {
                                            height 0.08
                                            radius 0.05
                                          }
                                          Sphere {
                                            radius 0.05
                                          }
                                          Sphere {
                                            radius 0.05
                                          }
                                        ]
                                      }
                                      physics Physics {
                                      }
                                    }
                                  }
                                ]
                                name "panda_link5"
                                boundingObject Group {
                                  children [
                                    Cylinder {
                                      height 0.1
                                      radius 0.06
                                    }
                                    Sphere {
                                      radius 0.06
                                    }
                                    Sphere {
                                      radius 0.06
                                    }
                                    Cylinder {
                                      height 0.14
                                      radius 0.025
                                    }
                                    Sphere {
                                      radius 0.025
                                    }
                                    Sphere {
                                      radius 0.025
                                    }
                                  ]
                                }
                                physics Physics {
                                }
                              }
                            }
                          ]
                          name "panda_link4"
                          boundingObject Group {
                            children [
                              Cylinder {
                                height 0.12
                                radius 0.06
                              }
                              Sphere {
                                radius 0.06
                              }
                              Sphere {
                                radius 0.06
                              }
                            ]
                          }
                          physics Physics {
                          }
                        }
                      }
                    ]
                    name "panda_link3"
                    boundingObject Group {
                      children [
                        Cylinder {
                          height 0.15
                          radius 0.06
                        }
                        Sphere {
                          radius 0.06
                        }
                        Sphere {
                          radius 0.06
                        }
                      ]
                    }
                    physics Physics {
                    }
                  }
                }
              ]
              name "panda_link2"
              boundingObject Group {
                children [
                  Cylinder {
                    height 0.12
                    radius 0.06
                  }
                  Sphere {
                    radius 0.06
                  }
                  Sphere {
                    radius 0.06
                  }
                ]
              }
              physics Physics {
              }
            }
          }
        ]
        name "panda_link1"
        boundingObject Group {
          children [
            Cylinder {
              height 0.283
              radius 0.06
            }
            Sphere {
              radius 0.06
            }
            Sphere {
              radius 0.06
            }
          ]
        }
        physics Physics {
        }
      }
    }
  ]
  name "Panda"
  boundingObject Group {
    children [
      Cylinder {
        height 0.03
        radius 0.06
      }
      Sphere {
        radius 0.06
      }
      Sphere {
        radius 0.06
      }
    ]
  }
  controller "RoboticArmIK"
  supervisor TRUE
}
